Workbook

Sheet RTD_20240620_TP24_BF_NodeResult
A1: CaseID | B1: DateTime | C1: Period | D1: Node | E1: Generation (MW) | F1: Load (MW) | G1: Price ($/MWh) | H1: Deficit(MW) | I1: Surplus(MW) | L1: CaseID | M1: DateTime | N1: Period | O1: Node | P1: Generation (MW) | Q1: Load (MW) | R1: Price ($/MWh) | S1: Deficit(MW) | T1: Surplus(MW)
A2: 191302024062300479 | B2: 45463.479 | C2: TP24 | D2: ABY0111 | E2: 0 | F2: 3.007 | G2: 269.3895 | H2: 0 | I2: 0 | J2: =F2-Q2 -> 0 | L2: 191302024062300479 | M2: 45463.479 | N2: TP24 | O2: ABY0111 | P2: 0 | Q2: 3.007 | R2: 269.3895 | S2: 0 | T2: 0
A3: 191302024062300479 | B3: 45463.479 | C3: TP24 | D3: ABY1101 | E3: 0 | F3: 0 | G3: 269.1015 | H3: 0 | I3: 0 | J3: =F3-Q3 -> 0 | L3: 191302024062300479 | M3: 45463.479 | N3: TP24 | O3: ABY1101 | P3: 0 | Q3: 0 | R3: 269.1015 | S3: 0 | T3: 0
A4: 191302024062300479 | B4: 45463.479 | C4: TP24 | D4: ALB0331 | E4: 0 | F4: 98.096 | G4: 274.621 | H4: 0 | I4: 0 | J4: =F4-Q4 -> 0 | L4: 191302024062300479 | M4: 45463.479 | N4: TP24 | O4: ALB0331 | P4: 0 | Q4: 98.096 | R4: 274.621 | S4: 0 | T4: 0
A5: 191302024062300479 | B5: 45463.479 | C5: TP24 | D5: ALB1101 | E5: 0 | F5: 34.237 | G5: 274.247 | H5: 0 | I5: 0 | J5: =F5-Q5 -> 0 | L5: 191302024062300479 | M5: 45463.479 | N5: TP24 | O5: ALB1101 | P5: 0 | Q5: 34.237 | R5: 274.247 | S5: 0 | T5: 0
A6: 191302024062300479 | B6: 45463.479 | C6: TP24 | D6: ALB2201 | E6: 0 | F6: 0 | G6: 273.9051 | H6: 0 | I6: 0 | J6: =F6-Q6 -> 0 | L6: 191302024062300479 | M6: 45463.479 | N6: TP24 | O6: ALB2201 | P6: 0 | Q6: 0 | R6: 273.9051 | S6: 0 | T6: 0
A7: 191302024062300479 | B7: 45463.479 | C7: TP24 | D7: APS0111 | E7: 0 | F7: 0.28 | G7: 277.5045 | H7: 0 | I7: 0 | J7: =F7-Q7 -> 0 | L7: 191302024062300479 | M7: 45463.479 | N7: TP24 | O7: APS0111 | P7: 0 | Q7: 0.28 | R7: 277.5045 | S7: 0 | T7: 0
A8: 191302024062300479 | B8: 45463.479 | C8: TP24 | D8: APS0661 | E8: 0 | F8: 0 | G8: 277.0236 | H8: 0 | I8: 0 | J8: =F8-Q8 -> 0 | L8: 191302024062300479 | M8: 45463.479 | N8: TP24 | O8: APS0661 | P8: 0 | Q8: 0 | R8: 277.0236 | S8: 0 | T8: 0
A9: 191302024062300479 | B9: 45463.479 | C9: TP24 | D9: ARA2201 | E9: 0 | F9: 0 | G9: 250.189 | H9: 0 | I9: 0 | J9: =F9-Q9 -> 0 | L9: 191302024062300479 | M9: 45463.479 | N9: TP24 | O9: ARA2201 | P9: 0 | Q9: 0 | R9: 250.189 | S9: 0 | T9: 0
A10: 191302024062300479 | B10: 45463.479 | C10: TP24 | D10: ARA2201 ARA0 | E10: 72 | F10: 0 | G10: 250.189 | H10: 0 | I10: 0 | J10: =F10-Q10 -> 0 | L10: 191302024062300479 | M10: 45463.479 | N10: TP24 | O10: ARA2201 ARA0 | P10: 72 | Q10: 0 | R10: 250.189 | S10: 0 | T10: 0
A11: 191302024062300479 | B11: 45463.479 | C11: TP24 | D11: ARG1101 | E11: 0 | F11: 0 | G11: 294.6714 | H11: 0 | I11: 0 | J11: =F11-Q11 -> 0 | L11: 191302024062300479 | M11: 45463.479 | N11: TP24 | O11: ARG1101 | P11: 0 | Q11: 0 | R11: 294.6714 | S11: 0 | T11: 0
A12: 191302024062300479 | B12: 45463.479 | C12: TP24 | D12: ARG1101 BRR0 | E12: 11 | F12: 0 | G12: 294.6714 | H12: 0 | I12: 0 | J12: =F12-Q12 -> 0 | L12: 191302024062300479 | M12: 45463.479 | N12: TP24 | O12: ARG1101 BRR0 | P12: 11 | Q12: 0 | R12: 294.6714 | S12: 0 | T12: 0
A13: 191302024062300479 | B13: 45463.479 | C13: TP24 | D13: ARI1101 | E13: 0 | F13: 0 | G13: 244.3526 | H13: 0 | I13: 0 | J13: =F13-Q13 -> 0 | L13: 191302024062300479 | M13: 45463.479 | N13: TP24 | O13: ARI1101 | P13: 0 | Q13: 0 | R13: 244.3526 | S13: 0 | T13: 0
... A3217: 191012024062355506 | B3217: 45463.497 | C3217: TP24 | D3217: WWD1103 WWD0 | E3217: 0 | F3217: 0 | G3217: 219.9732 | H3217: 0 | I3217: 0 | J3217: =F3217-Q3217 -> 0 | L3217: 191012024062355506 | M3217: 45463.497 | N3217: TP24 | O3217: WWD1103 WWD0 | P3217: 0 | Q3217: 0 | R3217: 219.9732 | S3217: 0 | T3217: 0

Sheet Solution Pnode
A1: I | B1: SOLUTION | C1: PNODE | D1: 1 | E1: INTERVAL | F1: PNODENAME | G1: PNODETYPE | H1: DISCONNECTED | I1: LOAD | J1: GENERATION | K1: INITIALMW | L1: PRICE | M1: LOCATIONFACTOR | N1: MW_IMBALANCE | O1: BADSCADAGEN | P1: BADSCADALOAD | Q1: REQDLOAD | R1: DEAD | S1: ENSHORTFALL | T1: RESERVEDEFICITSIXSECCE | U1: RESERVEDEFICITSIXTYSECCE | V1: INSTRUCTEDSHED | W1: INSTRUCTEDSHEDACTIVE | X1: LOADINITIALMWSOURCE | Y1: DISPATCHEDLOADINIT | Z1: DISPATCHEDGENINIT | AA1: RTDDIDESTIMATEINITIALMW | AB1: ELECTRICALISLAND | AC1: TRANSFERDUETOOUTAGE | AD1: OUTAGEBRANCH | AE1: ENSHORTFALLTRANSFEROFFMW | AF1: ENSHORTFALLTRANSFERONMW | AG1: ENSHORTFALLTRANSFERDESTPNODE | AH1: ENSHORTFALLTRANSFERDESTNOTFOUND | AI1: SHORTFALLDISABLEDSCALING | AJ1: PRICETRANSFERSOURCEPNODE | AK1: PRICETRANSFERSOURCENOTFOUND | AL1: DEADWITHLOAD | AM1: GENINITIALMWSOURCE | AN1: REPLACEDSURPLUSPRICE | AO1: GENRESIDUAL | AP1: DDBIDSLIMIT | AQ1: ENERGYGENRESIDUAL | AR1: CAPACITYGENRESIDUAL
A2: 191012024062345498 | B2: SOLUTION | C2: PNODE | D2: 1 | E2: 45463.49 | F2: ABY0111 | G2: X | H2: 0 | I2: 1.9865 | J2: 0 | K2: 2 | L2: 203.1972 | M2: 1.0521 | N2: 0 | O2: 0 | P2: 0 | Q2: 1.986 | R2: 0 | S2: 0 | T2: 0 | U2: 0 | V2: 0 | W2: 0 | X2: METER | Y2: 0 | Z2: 0 | AA2: 0 | AB2: 2 | AC2: 0 | AE2: 0 | AF2: 0 | AH2: 0 | AI2: 0 | AK2: 0 | AL2: 0 | AN2: 0 | AO2: 0 | AP2: 0 | AQ2: 0 | AR2: 0
A3: 191012024062345498 | B3: SOLUTION | C3: PNODE | D3: 1 | E3: 45463.49 | F3: ABY1101 | G3: A | H3: 0 | I3: 0 | J3: 0 | K3: 0 | L3: 202.98 | M3: 1.0509 | N3: 0 | O3: 0 | P3: 0 | Q3: 0 | R3: 0 | S3: 0 | T3: 0 | U3: 0 | V3: 0 | W3: 0 | Y3: 0 | Z3: 0 | AA3: 0 | AB3: 2 | AC3: 0 | AE3: 0 | AF3: 0 | AH3: 0 | AI3: 0 | AK3: 0 | AL3: 0 | AN3: 0 | AO3: 0 | AP3: 0 | AQ3: 0 | AR3: 0
A4: 191012024062345498 | B4: SOLUTION | C4: PNODE | D4: 1 | E4: 45463.49 | F4: ALB0331 | G4: X | H4: 0 | I4: 91.2861 | J4: 0 | K4: 92.2 | L4: 194.5025 | M4: 0.9996 | N4: 0 | O4: 0 | P4: 0 | Q4: 91.286 | R4: 0 | S4: 0 | T4: 0 | U4: 0 | V4: 0 | W4: 0 | X4: METER | Y4: 0 | Z4: 0 | AA4: 0 | AB4: 1 | AC4: 0 | AE4: 0 | AF4: 0 | AH4: 0 | AI4: 0 | AK4: 0 | AL4: 0 | AN4: 0 | AO4: 0 | AP4: 0 | AQ4: 0 | AR4: 0
A5: 191012024062345498 | B5: SOLUTION | C5: PNODE | D5: 1 | E5: 45463.49 | F5: ALB1101 | G5: X | H5: 0 | I5: 34.356 | J5: 0 | K5: 34.7 | L5: 194.2658 | M5: 0.9984 | N5: 0 | O5: 0 | P5: 0 | Q5: 34.356 | R5: 0 | S5: 0 | T5: 0 | U5: 0 | V5: 0 | W5: 0 | X5: METER | Y5: 0 | Z5: 0 | AA5: 0 | AB5: 1 | AC5: 0 | AE5: 0 | AF5: 0 | AH5: 0 | AI5: 0 | AK5: 0 | AL5: 0 | AN5: 0 | AO5: 0 | AP5: 0 | AQ5: 0 | AR5: 0
A6: 191012024062345498 | B6: SOLUTION | C6: PNODE | D6: 1 | E6: 45463.49 | F6: ALB2201 | G6: A | H6: 0 | I6: 0 | J6: 0 | K6: 0 | L6: 193.9955 | M6: 0.997 | N6: 0 | O6: 0 | P6: 0 | Q6: 0 | R6: 0 | S6: 0 | T6: 0 | U6: 0 | V6: 0 | W6: 0 | Y6: 0 | Z6: 0 | AA6: 0 | AB6: 1 | AC6: 0 | AE6: 0 | AF6: 0 | AH6: 0 | AI6: 0 | AK6: 0 | AL6: 0 | AN6: 0 | AO6: 0 | AP6: 0 | AQ6: 0 | AR6: 0
A7: 191012024062345498 | B7: SOLUTION | C7: PNODE | D7: 1 | E7: 45463.49 | F7: APS0111 | G7: X | H7: 0 | I7: 0.2771 | J7: 0 | K7: 0.279 | L7: 207.2326 | M7: 1.073 | N7: 0 | O7: 0 | P7: 0 | Q7: 0.277 | R7: 0 | S7: 0 | T7: 0 | U7: 0 | V7: 0 | W7: 0 | X7: SCADA | Y7: 0 | Z7: 0 | AA7: 0 | AB7: 2 | AC7: 0 | AE7: 0 | AF7: 0 | AH7: 0 | AI7: 0 | AK7: 0 | AL7: 0 | AN7: 0 | AO7: 0 | AP7: 0 | AQ7: 0 | AR7: 0
A8: 191012024062345498 | B8: SOLUTION | C8: PNODE | D8: 1 | E8: 45463.49 | F8: APS0661 | G8: A | H8: 0 | I8: 0 | J8: 0 | K8: 0 | L8: 206.8734 | M8: 1.0711 | N8: 0 | O8: 0 | P8: 0 | Q8: 0 | R8: 0 | S8: 0 | T8: 0 | U8: 0 | V8: 0 | W8: 0 | Y8: 0 | Z8: 0 | AA8: 0 | AB8: 2 | AC8: 0 | AE8: 0 | AF8: 0 | AH8: 0 | AI8: 0 | AK8: 0 | AL8: 0 | AN8: 0 | AO8: 0 | AP8: 0 | AQ8: 0 | AR8: 0
A9: 191012024062345498 | B9: SOLUTION | C9: PNODE | D9: 1 | E9: 45463.49 | F9: ARA2201 | G9: A | H9: 0 | I9: 0 | J9: 0 | K9: 0 | L9: 179.978 | M9: 0.9249 | N9: 0 | O9: 0 | P9: 0 | Q9: 0 | R9: 0 | S9: 0 | T9: 0 | U9: 0 | V9: 0 | W9: 0 | Y9: 0 | Z9: 0 | AA9: 0 | AB9: 1 | AC9: 0 | AE9: 0 | AF9: 0 | AH9: 0 | AI9: 0 | AK9: 0 | AL9: 0 | AN9: 0 | AO9: 0 | AP9: 0 | AQ9: 0 | AR9: 0
A10: 191012024062345498 | B10: SOLUTION | C10: PNODE | D10: 1 | E10: 45463.49 | F10: ARA2201 ARA0 | G10: I | H10: 0 | I10: 0 | J10: 47 | K10: 63.096 | L10: 179.978 | M10: 0.9249 | N10: 0 | O10: 0 | P10: 0 | Q10: 0 | R10: 0 | S10: 0 | T10: 0 | U10: 0 | V10: 0 | W10: 0 | Y10: 0 | Z10: 0 | AA10: 0 | AB10: 1 | AC10: 0 | AE10: 0 | AF10: 0 | AH10: 0 | AI10: 0 | AK10: 0 | AL10: 0 | AM10: SCADA | AN10: 0 | AO10: 30 | AP10: 0 | AQ10: 31 | AR10: 30
A11: 191012024062345498 | B11: SOLUTION | C11: PNODE | D11: 1 | E11: 45463.49 | F11: ARG1101 | G11: X | H11: 0 | I11: 0 | J11: 0 | K11: 0 | L11: 222.4605 | M11: 1.1518 | N11: 0 | O11: 0 | P11: 0 | Q11: 0 | R11: 0 | S11: 0 | T11: 0 | U11: 0 | V11: 0 | W11: 0 | X11: SCADA | Y11: 0 | Z11: 0 | AA11: 0 | AB11: 2 | AC11: 0 | AE11: 0 | AF11: 0 | AH11: 0 | AI11: 0 | AK11: 0 | AL11: 0 | AN11: 0 | AO11: 0 | AP11: 0 | AQ11: 0 | AR11: 0
A12: 191012024062345498 | B12: SOLUTION | C12: PNODE | D12: 1 | E12: 45463.49 | F12: ARG1101 BRR0 | G12: I | H12: 0 | I12: 0 | J12: 11 | K12: 10.9 | L12: 222.4605 | M12: 1.1518 | N12: 0 | O12: 0 | P12: 0 | Q12: 0 | R12: 0 | S12: 0 | T12: 0 | U12: 0 | V12: 0 | W12: 0 | Y12: 0 | Z12: 0 | AA12: 0 | AB12: 2 | AC12: 0 | AE12: 0 | AF12: 0 | AH12: 0 | AI12: 0 | AK12: 0 | AL12: 0 | AM12: SCADA | AN12: 0 | AO12: 0 | AP12: 0 | AQ12: 0 | AR12: 0
A13: 191012024062345498 | B13: SOLUTION | C13: PNODE | D13: 1 | E13: 45463.49 | F13: ARI1101 | G13: X | H13: 0 | I13: 0 | J13: 0 | K13: 0 | L13: 176.4655 | M13: 0.9069 | N13: 0 | O13: 0 | P13: 0 | Q13: 0 | R13: 0 | S13: 0 | T13: 0 | U13: 0 | V13: 0 | W13: 0 | X13: SCADA | Y13: 0 | Z13: 0 | AA13: 0 | AB13: 1 | AC13: 0 | AE13: 0 | AF13: 0 | AH13: 0 | AI13: 0 | AK13: 0 | AL13: 0 | AN13: 0 | AO13: 0 | AP13: 0 | AQ13: 0 | AR13: 0
A14: 191012024062345498 | B14: SOLUTION | C14: PNODE | D14: 1 | E14: 45463.49 | F14: ARI1101 ARI0 | G14: I | H14: 0 | I14: 0 | J14: 46 | K14: 74.389 | L14: 176.4655 | M14: 0.9069 | N14: 0 | O14: 0 | P14: 0 | Q14: 0 | R14: 0 | S14: 0 | T14: 0 | U14: 0 | V14: 0 | W14: 0 | Y14: 0 | Z14: 0 | AA14: 0 | AB14: 1 | AC14: 0 | AE14: 0 | AF14: 0 | AH14: 0 | AI14: 0 | AK14: 0 | AL14: 0 | AM14: SCADA | AN14: 0 | AO14: 35 | AP14: 0 | AQ14: 35 | AR14: 35
A15: 191012024062345498 | B15: SOLUTION | C15: PNODE | D15: 1 | E15: 45463.49 | F15: ARI1102 | G15: X | H15: 0 | I15: 10.5939 | J15: 0 | K15: 10.7 | L15: 187.0198 | M15: 0.9611 | N15: 0 | O15: 0 | P15: 0 | Q15: 10.594 | R15: 0 | S15: 0 | T15: 0 | U15: 0 | V15: 0 | W15: 0 | X15: METER | Y15: 0 | Z15: 0 | AA15: 0 | AB15: 1 | AC15: 0 | AE15: 0 | AF15: 0 | AH15: 0 | AI15: 0 | AK15: 0 | AL15: 0 | AN15: 0 | AO15: 0 | AP15: 0 | AQ15: 0 | AR15: 0
A16: 191012024062345498 | B16: SOLUTION | C16: PNODE | D16: 1 | E16: 45463.49 | F16: ARI1102 ARI0 | G16: I | H16: 0 | I16: 0 | J16: 40 | K16: 42.805 | L16: 187.0198 | M16: 0.9611 | N16: 0 | O16: 0 | P16: 0 | Q16: 0 | R16: 0 | S16: 0 | T16: 0 | U16: 0 | V16: 0 | W16: 0 | Y16: 0 | Z16: 0 | AA16: 0 | AB16: 1 | AC16: 0 | AE16: 0 | AF16: 0 | AH16: 0 | AI16: 0 | AK16: 0 | AL16: 0 | AM16: SCADA | AN16: 0 | AO16: 47 | AP16: 0 | AQ16: 50 | AR16: 47
A17: 191012024062345498 | B17: SOLUTION | C17: PNODE | D17: 1 | E17: 45463.49 | F17: ASB0661 | G17: X | H17: 0 | I17: 61.3 | J17: 0 | K17: 61.3 | L17: 205.9737 | M17: 1.0664 | N17: 0 | O17: 0 | P17: 0 | Q17: 61.3 | R17: 0 | S17: 0 | T17: 0 | U17: 0 | V17: 0 | W17: 0 | X17: METER | Y17: 0 | Z17: 0 | AA17: 0 | AB17: 2 | AC17: 0 | AE17: 0 | AF17: 0 | AH17: 0 | AI17: 0 | AK17: 0 | AL17: 0 | AN17: 0 | AO17: 0 | AP17: 0 | AQ17: 0 | AR17: 0
A18: 191012024062345498 | B18: SOLUTION | C18: PNODE | D18: 1 | E18: 45463.49 | F18: ASB0661 HBK0 | G18: I | H18: 0 | I18: 0 | J18: 22 | K18: 22.6 | L18: 205.9737 | M18: 1.0664 | N18: 0 | O18: 0 | P18: 0 | Q18: 0 | R18: 0 | S18: 0 | T18: 0 | U18: 0 | V18: 0 | W18: 0 | Y18: 0 | Z18: 0 | AA18: 0 | AB18: 2 | AC18: 0 | AE18: 0 | AF18: 0 | AH18: 0 | AI18: 0 | AK18: 0 | AL18: 0 | AM18: SCADA | AN18: 0 | AO18: 2 | AP18: 0 | AQ18: 2 | AR18: 6
A19: 191012024062345498 | B19: SOLUTION | C19: PNODE | D19: 1 | E19: 45463.49 | F19: ASB2201 | G19: A | H19: 0 | I19: 0 | J19: 0 | K19: 0 | L19: 205.8642 | M19: 1.0659 | N19: 0 | O19: 0 | P19: 0 | Q19: 0 | R19: 0 | S19: 0 | T19: 0 | U19: 0 | V19: 0 | W19: 0 | Y19: 0 | Z19: 0 | AA19: 0 | AB19: 2 | AC19: 0 | AE19: 0 | AF19: 0 | AH19: 0 | AI19: 0 | AK19: 0 | AL19: 0 | AN19: 0 | AO19: 0 | AP19: 0 | AQ19: 0 | AR19: 0
A20: 191012024062345498 | B20: SOLUTION | C20: PNODE | D20: 1 | E20: 45463.49 | F20: ASY0111 | G20: X | H20: 0 | I20: 12.6142 | J20: 0 | K20: 12.7 | L20: 228.091 | M20: 1.1809 | N20: 0 | O20: 0 | P20: 0 | Q20: 12.614 | R20: 0 | S20: 0 | T20: 0 | U20: 0 | V20: 0 | W20: 0 | X20: METER | Y20: 0 | Z20: 0 | AA20: 0 | AB20: 2 | AC20: 0 | AE20: 0 | AF20: 0 | AH20: 0 | AI20: 0 | AK20: 0 | AL20: 0 | AN20: 0 | AO20: 0 | AP20: 0 | AQ20: 0 | AR20: 0
A21: 191012024062345498 | B21: SOLUTION | C21: PNODE | D21: 1 | E21: 45463.49 | F21: ASY0661 | G21: A | H21: 0 | I21: 0 | J21: 0 | K21: 0 | L21: 227.9293 | M21: 1.1801 | N21: 0 | O21: 0 | P21: 0 | Q21: 0 | R21: 0 | S21: 0 | T21: 0 | U21: 0 | V21: 0 | W21: 0 | Y21: 0 | Z21: 0 | AA21: 0 | AB21: 2 | AC21: 0 | AE21: 0 | AF21: 0 | AH21: 0 | AI21: 0 | AK21: 0 | AL21: 0 | AN21: 0 | AO21: 0 | AP21: 0 | AQ21: 0 | AR21: 0
A22: 191012024062345498 | B22: SOLUTION | C22: PNODE | D22: 1 | E22: 45463.49 | F22: ATI2201 | G22: X | H22: 0 | I22: 0 | J22: 0 | K22: 0 | L22: 180.7598 | M22: 0.929 | N22: 0 | O22: 0 | P22: 0 | Q22: 0 | R22: 0 | S22: 0 | T22: 0 | U22: 0 | V22: 0 | W22: 0 | X22: SCADA | Y22: 0 | Z22: 0 | AA22: 0 | AB22: 1 | AC22: 0 | AE22: 0 | AF22: 0 | AH22: 0 | AI22: 0 | AK22: 0 | AL22: 0 | AN22: 0 | AO22: 0 | AP22: 0 | AQ22: 0 | AR22: 0
A23: 191012024062345498 | B23: SOLUTION | C23: PNODE | D23: 1 | E23: 45463.49 | F23: ATI2201 ATI0 | G23: I | H23: 0 | I23: 0 | J23: 51 | K23: 16.826 | L23: 180.7598 | M23: 0.929 | N23: 0 | O23: 0 | P23: 0 | Q23: 0 | R23: 0 | S23: 0 | T23: 0 | U23: 0 | V23: 0 | W23: 0 | Y23: 0 | Z23: 0 | AA23: 0 | AB23: 1 | AC23: 0 | AE23: 0 | AF23: 0 | AH23: 0 | AI23: 0 | AK23: 0 | AL23: 0 | AM23: SCADA | AN23: 0 | AO23: 18 | AP23: 0 | AQ23: 23 | AR23: 18
A24: 191012024062345498 | B24: SOLUTION | C24: PNODE | D24: 1 | E24: 45463.49 | F24: AVI2201 | G24: X | H24: 0 | I24: 0 | J24: 0 | K24: 0 | L24: 193.2498 | M24: 1.0006 | N24: 0 | O24: 0 | P24: 0 | Q24: 0 | R24: 0 | S24: 0 | T24: 0 | U24: 0 | V24: 0 | W24: 0 | X24: SCADA | Y24: 0 | Z24: 0 | AA24: 0 | AB24: 2 | AC24: 0 | AE24: 0 | AF24: 0 | AH24: 0 | AI24: 0 | AK24: 0 | AL24: 0 | AN24: 0 | AO24: 0 | AP24: 0 | AQ24: 0 | AR24: 0
A25: 191012024062345498 | B25: SOLUTION | C25: PNODE | D25: 1 | E25: 45463.49 | F25: AVI2201 AVI0 | G25: I | H25: 0 | I25: 0 | J25: 104.218 | K25: 93.6 | L25: 193.2498 | M25: 1.0006 | N25: 0 | O25: 0 | P25: 0 | Q25: 0 | R25: 0 | S25: 0 | T25: 0 | U25: 0 | V25: 0 | W25: 0 | Y25: 0 | Z25: 0 | AA25: 0 | AB25: 2 | AC25: 0 | AE25: 0 | AF25: 0 | AH25: 0 | AI25: 0 | AK25: 0 | AL25: 0 | AM25: SCADA | AN25: 0 | AO25: 104.378 | AP25: 0 | AQ25: 110.782 | AR25: 104.378
A26: 191012024062345498 | B26: SOLUTION | C26: PNODE | D26: 1 | E26: 45463.49 | F26: BAL0331 | G26: X | H26: 0 | I26: 20.5214 | J26: 0 | K26: 20.661 | L26: 206.4871 | M26: 1.0691 | N26: 0 | O26: 0 | P26: 0 | Q26: 20.521 | R26: 0 | S26: 0 | T26: 0 | U26: 0 | V26: 0 | W26: 0 | X26: SE | Y26: 0 | Z26: 0 | AA26: 0 | AB26: 2 | AC26: 0 | AE26: 0 | AF26: 0 | AH26: 0 | AI26: 0 | AK26: 0 | AL26: 0 | AN26: 0 | AO26: 0 | AP26: 0 | AQ26: 0 | AR26: 0
A27: 191012024062345498 | B27: SOLUTION | C27: PNODE | D27: 1 | E27: 45463.49 | F27: BAL1101 | G27: A | H27: 0 | I27: 0 | J27: 0 | K27: 0 | L27: 203.9434 | M27: 1.0559 | N27: 0 | O27: 0 | P27: 0 | Q27: 0 | R27: 0 | S27: 0 | T27: 0 | U27: 0 | V27: 0 | W27: 0 | Y27: 0 | Z27: 0 | AA27: 0 | AB27: 2 | AC27: 0 | AE27: 0 | AF27: 0 | AH27: 0 | AI27: 0 | AK27: 0 | AL27: 0 | AN27: 0 | AO27: 0 | AP27: 0 | AQ27: 0 | AR27: 0
A28: 191012024062345498 | B28: SOLUTION | C28: PNODE | D28: 1 | E28: 45463.49 | F28: BDE0111 | G28: X | H28: 0 | I28: 3.079 | J28: 0 | K28: 3.1 | L28: 195.6464 | M28: 1.013 | N28: 0 | O28: 0 | P28: 0 | Q28: 3.079 | R28: 0 | S28: 0 | T28: 0 | U28: 0 | V28: 0 | W28: 0 | X28: METER | Y28: 0 | Z28: 0 | AA28: 0 | AB28: 2 | AC28: 0 | AE28: 0 | AF28: 0 | AH28: 0 | AI28: 0 | AK28: 0 | AL28: 0 | AN28: 0 | AO28: 0 | AP28: 0 | AQ28: 0 | AR28: 0
A29: 191012024062345498 | B29: SOLUTION | C29: PNODE | D29: 1 | E29: 45463.49 | F29: BDE1101 | G29: A | H29: 0 | I29: 0 | J29: 0 | K29: 0 | L29: 195.5131 | M29: 1.0123 | N29: 0 | O29: 0 | P29: 0 | Q29: 0 | R29: 0 | S29: 0 | T29: 0 | U29: 0 | V29: 0 | W29: 0 | Y29: 0 | Z29: 0 | AA29: 0 | AB29: 2 | AC29: 0 | AE29: 0 | AF29: 0 | AH29: 0 | AI29: 0 | AK29: 0 | AL29: 0 | AN29: 0 | AO29: 0 | AP29: 0 | AQ29: 0 | AR29: 0
A30: 191012024062345498 | B30: SOLUTION | C30: PNODE | D30: 1 | E30: 45463.49 | F30: BEN2201 | G30: A | H30: 0 | I30: 0 | J30: 0 | K30: 0 | L30: 193.1423 | M30: 1 | N30: 0 | O30: 0 | P30: 0 | Q30: 0 | R30: 0 | S30: 0 | T30: 0 | U30: 0 | V30: 0 | W30: 0 | Y30: 0 | Z30: 0 | AA30: 0 | AB30: 2 | AC30: 0 | AE30: 0 | AF30: 0 | AH30: 0 | AI30: 0 | AK30: 0 | AL30: 0 | AN30: 0 | AO30: 0 | AP30: 0 | AQ30: 0 | AR30: 0
A31: 191012024062345498 | B31: SOLUTION | C31: PNODE | D31: 1 | E31: 45463.49 | F31: BEN2202 | G31: X | H31: 0 | I31: 0 | J31: 0 | K31: 0 | L31: 193.1423 | M31: 1 | N31: 0 | O31: 0 | P31: 0 | Q31: 0 | R31: 0 | S31: 0 | T31: 0 | U31: 0 | V31: 0 | W31: 0 | X31: SE | Y31: 0 | Z31: 0 | AA31: 0 | AB31: 2 | AC31: 0 | AE31: 0 | AF31: 0 | AH31: 0 | AI31: 0 | AK31: 0 | AL31: 0 | AN31: 0 | AO31: 0 | AP31: 0 | AQ31: 0 | AR31: 0
A32: 191012024062345498 | B32: SOLUTION | C32: PNODE | D32: 1 | E32: 45463.49 | F32: BEN2202 BEN0 | G32: I | H32: 0 | I32: 0 | J32: 227.341 | K32: 147.98 | L32: 193.1423 | M32: 1 | N32: 0 | O32: 0 | P32: 0 | Q32: 0 | R32: 0 | S32: 0 | T32: 0 | U32: 0 | V32: 0 | W32: 0 | Y32: 0 | Z32: 0 | AA32: 0 | AB32: 2 | AC32: 0 | AE32: 0 | AF32: 0 | AH32: 0 | AI32: 0 | AK32: 0 | AL32: 0 | AM32: SCADA | AN32: 0 | AO32: 227.69 | AP32: 0 | AQ32: 241.659 | AR32: 227.69
A33: 191012024062345498 | B33: SOLUTION | C33: PNODE | D33: 1 | E33: 45463.49 | F33: BEN3502 | G33: A | H33: 0 | I33: 0 | J33: 0 | K33: 0 | L33: 193.1423 | M33: 1 | N33: 0 | O33: 0 | P33: 0 | Q33: 0 | R33: 0 | S33: 0 | T33: 0 | U33: 0 | V33: 0 | W33: 0 | Y33: 0 | Z33: 0 | AA33: 0 | AB33: 2 | AC33: 0 | AE33: 0 | AF33: 0 | AH33: 0 | AI33: 0 | AK33: 0 | AL33: 0 | AN33: 0 | AO33: 0 | AP33: 0 | AQ33: 0 | AR33: 0
A34: 191012024062345498 | B34: SOLUTION | C34: PNODE | D34: 1 | E34: 45463.49 | F34: BEN3503 | G34: A | H34: 0 | I34: 0 | J34: 0 | K34: 0 | L34: 193.1423 | M34: 1 | N34: 0 | O34: 0 | P34: 0 | Q34: 0 | R34: 0 | S34: 0 | T34: 0 | U34: 0 | V34: 0 | W34: 0 | Y34: 0 | Z34: 0 | AA34: 0 | AB34: 2 | AC34: 0 | AE34: 0 | AF34: 0 | AH34: 0 | AI34: 0 | AK34: 0 | AL34: 0 | AN34: 0 | AO34: 0 | AP34: 0 | AQ34: 0 | AR34: 0
A35: 191012024062345498 | B35: SOLUTION | C35: PNODE | D35: 1 | E35: 45463.49 | F35: BHL2201 | G35: A | H35: 0 | I35: 0 | J35: 0 | K35: 0 | L35: 192.8894 | M35: 0.9913 | N35: 0 | O35: 0 | P35: 0 | Q35: 0 | R35: 0 | S35: 0 | T35: 0 | U35: 0 | V35: 0 | W35: 0 | Y35: 0 | Z35: 0 | AA35: 0 | AB35: 1 | AC35: 0 | AE35: 0 | AF35: 0 | AH35: 0 | AI35: 0 | AK35: 0 | AL35: 0 | AN35: 0 | AO35: 0 | AP35: 0 | AQ35: 0 | AR35: 0
A36: 191012024062345498 | B36: SOLUTION | C36: PNODE | D36: 1 | E36: 45463.49 | F36: BHL2202 | G36: A | H36: 1 | I36: 0 | J36: 0 | K36: 0 | L36: 0 | M36: 0 | N36: 0 | O36: 0 | P36: 0 | Q36: 0 | R36: 1 | S36: 0 | T36: 0 | U36: 0 | V36: 0 | W36: 0 | Y36: 0 | Z36: 0 | AA36: 0 | AB36: 0 | AC36: 0 | AE36: 0 | AF36: 0 | AH36: 0 | AI36: 0 | AK36: 1 | AL36: 0 | AN36: 0 | AO36: 0 | AP36: 0 | AQ36: 0 | AR36: 0
A37: 191012024062345498 | B37: SOLUTION | C37: PNODE | D37: 1 | E37: 45463.49 | F37: BLN0331 | G37: X | H37: 0 | I37: 58.5019 | J37: 0 | K37: 58.9 | L37: 231.5127 | M37: 1.1987 | N37: 0 | O37: 0 | P37: 0 | Q37: 58.502 | R37: 0 | S37: 0 | T37: 0 | U37: 0 | V37: 0 | W37: 0 | X37: METER | Y37: 0 | Z37: 0 | AA37: 0 | AB37: 2 | AC37: 0 | AE37: 0 | AF37: 0 | AH37: 0 | AI37: 0 | AK37: 0 | AL37: 0 | AN37: 0 | AO37: 0 | AP37: 0 | AQ37: 0 | AR37: 0
A38: 191012024062345498 | B38: SOLUTION | C38: PNODE | D38: 1 | E38: 45463.49 | F38: BLN1101 | G38: A | H38: 0 | I38: 0 | J38: 0 | K38: 0 | L38: 230.8826 | M38: 1.1954 | N38: 0 | O38: 0 | P38: 0 | Q38: 0 | R38: 0 | S38: 0 | T38: 0 | U38: 0 | V38: 0 | W38: 0 | Y38: 0 | Z38: 0 | AA38: 0 | AB38: 2 | AC38: 0 | AE38: 0 | AF38: 0 | AH38: 0 | AI38: 0 | AK38: 0 | AL38: 0 | AN38: 0 | AO38: 0 | AP38: 0 | AQ38: 0 | AR38: 0
A39: 191012024062345498 | B39: SOLUTION | C39: PNODE | D39: 1 | E39: 45463.49 | F39: BOB1101 | G39: X | H39: 0 | I39: 64.4547 | J39: 0 | K39: 65.1 | L39: 191.6133 | M39: 0.9847 | N39: 0 | O39: 0 | P39: 0 | Q39: 64.455 | R39: 0 | S39: 0 | T39: 0 | U39: 0 | V39: 0 | W39: 0 | X39: SCADA | Y39: 0 | Z39: 0 | AA39: 0 | AB39: 1 | AC39: 0 | AE39: 0 | AF39: 0 | AH39: 0 | AI39: 0 | AK39: 0 | AL39: 0 | AN39: 0 | AO39: 0 | AP39: 0 | AQ39: 0 | AR39: 0
A40: 191012024062345498 | B40: SOLUTION | C40: PNODE | D40: 1 | E40: 45463.49 | F40: BOB2204 | G40: A | H40: 0 | I40: 0 | J40: 0 | K40: 0 | L40: 191.6848 | M40: 0.9851 | N40: 0 | O40: 0 | P40: 0 | Q40: 0 | R40: 0 | S40: 0 | T40: 0 | U40: 0 | V40: 0 | W40: 0 | Y40: 0 | Z40: 0 | AA40: 0 | AB40: 1 | AC40: 0 | AE40: 0 | AF40: 0 | AH40: 0 | AI40: 0 | AK40: 0 | AL40: 0 | AN40: 0 | AO40: 0 | AP40: 0 | AQ40: 0 | AR40: 0
...

Sheet Sheet2
A1: CaseID | B1: DateTime | C1: Period | D1: Node | E1: Generation (MW) | F1: Load (MW) | G1: Price ($/MWh) | H1: Deficit(MW) | I1: Surplus(MW) | J1: GENERATION | K1: LOAD | L1: PRICE | M1: INITIALMW | N1: Node Re | O1: LOAD
A2: 191012024062345498 | B2: 45463.49 | C2: TP24 | D2: ABY0111 | E2: 0 | F2: 1.9865 | G2: 203.1972 | H2: 0 | I2: 0 | J2: =VLOOKUP($D2,'Solution Pnode'!$F:$L,5,FALSE) -> 0 | K2: =VLOOKUP($D2,'Solution Pnode'!$F:$L,4,FALSE) -> 1.9865 | L2: =VLOOKUP($D2,'Solution Pnode'!$F:$L,7,FALSE) -> 203.1972 | M2: =VLOOKUP($D2,'Solution Pnode'!$F:$L,6,FALSE) -> 2 | N2: =J2-E2 -> 0 | O2: =K2-F2 -> 0 | P2: =L2-G2 -> 0
A3: 191012024062345498 | B3: 45463.49 | C3: TP24 | D3: ABY1101 | E3: 0 | F3: 0 | G3: 202.98 | H3: 0 | I3: 0 | J3: =VLOOKUP($D3,'Solution Pnode'!$F:$L,5,FALSE) -> 0 | K3: =VLOOKUP($D3,'Solution Pnode'!$F:$L,4,FALSE) -> 0 | L3: =VLOOKUP($D3,'Solution Pnode'!$F:$L,7,FALSE) -> 202.98 | M3: =VLOOKUP($D3,'Solution Pnode'!$F:$L,6,FALSE) -> 0 | N3: =J3-E3 -> 0 | O3: =K3-F3 -> 0 | P3: =L3-G3 -> 0
A4: 191012024062345498 | B4: 45463.49 | C4: TP24 | D4: ALB0331 | E4: 0 | F4: 91.2861 | G4: 194.5025 | H4: 0 | I4: 0 | J4: =VLOOKUP($D4,'Solution Pnode'!$F:$L,5,FALSE) -> 0 | K4: =VLOOKUP($D4,'Solution Pnode'!$F:$L,4,FALSE) -> 91.2861 | L4: =VLOOKUP($D4,'Solution Pnode'!$F:$L,7,FALSE) -> 194.5025 | M4: =VLOOKUP($D4,'Solution Pnode'!$F:$L,6,FALSE) -> 92.2 | N4: =J4-E4 -> 0 | O4: =K4-F4 -> 0 | P4: =L4-G4 -> 0
A5: 191012024062345498 | B5: 45463.49 | C5: TP24 | D5: ALB1101 | E5: 0 | F5: 34.3561 | G5: 194.2658 | H5: 0 | I5: 0 | J5: =VLOOKUP($D5,'Solution Pnode'!$F:$L,5,FALSE) -> 0 | K5: =VLOOKUP($D5,'Solution Pnode'!$F:$L,4,FALSE) -> 34.356 | L5: =VLOOKUP($D5,'Solution Pnode'!$F:$L,7,FALSE) -> 194.2658 | M5: =VLOOKUP($D5,'Solution Pnode'!$F:$L,6,FALSE) -> 34.7 | N5: =J5-E5 -> 0 | O5: =K5-F5 -> -0.0001 | P5: =L5-G5 -> 0
A6: 191012024062345498 | B6: 45463.49 | C6: TP24 | D6: ALB2201 | E6: 0 | F6: 0 | G6: 193.9955 | H6: 0 | I6: 0 | J6: =VLOOKUP($D6,'Solution Pnode'!$F:$L,5,FALSE) -> 0 | K6: =VLOOKUP($D6,'Solution Pnode'!$F:$L,4,FALSE) -> 0 | L6: =VLOOKUP($D6,'Solution Pnode'!$F:$L,7,FALSE) -> 193.9955 | M6: =VLOOKUP($D6,'Solution Pnode'!$F:$L,6,FALSE) -> 0 | N6: =J6-E6 -> 0 | O6: =K6-F6 -> 0 | P6: =L6-G6 -> 0
A7: 191012024062345498 | B7: 45463.49 | C7: TP24 | D7: APS0111 | E7: 0 | F7: 0.2771 | G7: 207.2326 | H7: 0 | I7: 0 | J7: =VLOOKUP($D7,'Solution Pnode'!$F:$L,5,FALSE) -> 0 | K7: =VLOOKUP($D7,'Solution Pnode'!$F:$L,4,FALSE) -> 0.2771 | L7: =VLOOKUP($D7,'Solution Pnode'!$F:$L,7,FALSE) -> 207.2326 | M7: =VLOOKUP($D7,'Solution Pnode'!$F:$L,6,FALSE) -> 0.279 | N7: =J7-E7 -> 0 | O7: =K7-F7 -> 0 | P7: =L7-G7 -> 0
A8: 191012024062345498 | B8: 45463.49 | C8: TP24 | D8: APS0661 | E8: 0 | F8: 0 | G8: 206.8734 | H8: 0 | I8: 0 | J8: =VLOOKUP($D8,'Solution Pnode'!$F:$L,5,FALSE) -> 0 | K8: =VLOOKUP($D8,'Solution Pnode'!$F:$L,4,FALSE) -> 0 | L8: =VLOOKUP($D8,'Solution Pnode'!$F:$L,7,FALSE) -> 206.8734 | M8: =VLOOKUP($D8,'Solution Pnode'!$F:$L,6,FALSE) -> 0 | N8: =J8-E8 -> 0 | O8: =K8-F8 -> 0 | P8: =L8-G8 -> 0
A9: 191012024062345498 | B9: 45463.49 | C9: TP24 | D9: ARA2201 | E9: 0 | F9: 0 | G9: 179.978 | H9: 0 | I9: 0 | J9: =VLOOKUP($D9,'Solution Pnode'!$F:$L,5,FALSE) -> 0 | K9: =VLOOKUP($D9,'Solution Pnode'!$F:$L,4,FALSE) -> 0 | L9: =VLOOKUP($D9,'Solution Pnode'!$F:$L,7,FALSE) -> 179.978 | M9: =VLOOKUP($D9,'Solution Pnode'!$F:$L,6,FALSE) -> 0 | N9: =J9-E9 -> 0 | O9: =K9-F9 -> 0 | P9: =L9-G9 -> 0
A10: 191012024062345498 | B10: 45463.49 | C10: TP24 | D10: ARA2201 ARA0 | E10: 47 | F10: 0 | G10: 179.978 | H10: 0 | I10: 0 | J10: =VLOOKUP($D10,'Solution Pnode'!$F:$L,5,FALSE) -> 47 | K10: =VLOOKUP($D10,'Solution Pnode'!$F:$L,4,FALSE) -> 0 | L10: =VLOOKUP($D10,'Solution Pnode'!$F:$L,7,FALSE) -> 179.978 | M10: =VLOOKUP($D10,'Solution Pnode'!$F:$L,6,FALSE) -> 63.096 | N10: =J10-E10 -> 0 | O10: =K10-F10 -> 0 | P10: =L10-G10 -> 0
A11: 191012024062345498 | B11: 45463.49 | C11: TP24 | D11: ARG1101 | E11: 0 | F11: 0 | G11: 222.4605 | H11: 0 | I11: 0 | J11: =VLOOKUP($D11,'Solution Pnode'!$F:$L,5,FALSE) -> 0 | K11: =VLOOKUP($D11,'Solution Pnode'!$F:$L,4,FALSE) -> 0 | L11: =VLOOKUP($D11,'Solution Pnode'!$F:$L,7,FALSE) -> 222.4605 | M11: =VLOOKUP($D11,'Solution Pnode'!$F:$L,6,FALSE) -> 0 | N11: =J11-E11 -> 0 | O11: =K11-F11 -> 0 | P11: =L11-G11 -> 0
A12: 191012024062345498 | B12: 45463.49 | C12: TP24 | D12: ARG1101 BRR0 | E12: 11 | F12: 0 | G12: 222.4605 | H12: 0 | I12: 0 | J12: =VLOOKUP($D12,'Solution Pnode'!$F:$L,5,FALSE) -> 11 | K12: =VLOOKUP($D12,'Solution Pnode'!$F:$L,4,FALSE) -> 0 | L12: =VLOOKUP($D12,'Solution Pnode'!$F:$L,7,FALSE) -> 222.4605 | M12: =VLOOKUP($D12,'Solution Pnode'!$F:$L,6,FALSE) -> 10.9 | N12: =J12-E12 -> 0 | O12: =K12-F12 -> 0 | P12: =L12-G12 -> 0
A13: 191012024062345498 | B13: 45463.49 | C13: TP24 | D13: ARI1101 | E13: 0 | F13: 0 | G13: 176.4655 | H13: 0 | I13: 0 | J13: =VLOOKUP($D13,'Solution Pnode'!$F:$L,5,FALSE) -> 0 | K13: =VLOOKUP($D13,'Solution Pnode'!$F:$L,4,FALSE) -> 0 | L13: =VLOOKUP($D13,'Solution Pnode'!$F:$L,7,FALSE) -> 176.4655 | M13: =VLOOKUP($D13,'Solution Pnode'!$F:$L,6,FALSE) -> 0 | N13: =J13-E13 -> 0 | O13: =K13-F13 -> 0 | P13: =L13-G13 -> 0
... A22: 191012024062345498 | B22: 45463.49 | C22: TP24 | D22: ATI2201 | E22: 0 | F22: 0 | G22: 180.7598 | H22: 0 | I22: 0 | J22: =VLOOKUP($D22,'Solution Pnode'!$F:$L,5,FALSE) -> 0 | K22: =VLOOKUP($D22,'Solution Pnode'!$F:$L,4,FALSE) -> 0 | L22: =VLOOKUP($D22,'Solution Pnode'!$F:$L,7,FALSE) -> 180.7598 | M22: =VLOOKUP($D22,'Solution Pnode'!$F:$L,6,FALSE) -> 0 | N22: =J22-E22 -> 0 | O22: =K22-F22 -> 0 | P22: =L22-G22 -> 0
A23: 191012024062345498 | B23: 45463.49 | C23: TP24 | D23: ATI2201 ATI0 | E23: 51 | F23: 0 | G23: 180.7598 | H23: 0 | I23: 0 | J23: =VLOOKUP($D23,'Solution Pnode'!$F:$L,5,FALSE) -> 51 | K23: =VLOOKUP($D23,'Solution Pnode'!$F:$L,4,FALSE) -> 0 | L23: =VLOOKUP($D23,'Solution Pnode'!$F:$L,7,FALSE) -> 180.7598 | M23: =VLOOKUP($D23,'Solution Pnode'!$F:$L,6,FALSE) -> 16.826 | N23: =J23-E23 -> 0 | O23: =K23-F23 -> 0 | P23: =L23-G23 -> 0 | U23: =18/10000 -> 0.0018
A24: 191012024062345498 | B24: 45463.49 | C24: TP24 | D24: AVI2201 | E24: 0 | F24: 0 | G24: 193.2498 | H24: 0 | I24: 0 | J24: =VLOOKUP($D24,'Solution Pnode'!$F:$L,5,FALSE) -> 0 | K24: =VLOOKUP($D24,'Solution Pnode'!$F:$L,4,FALSE) -> 0 | L24: =VLOOKUP($D24,'Solution Pnode'!$F:$L,7,FALSE) -> 193.2498 | M24: =VLOOKUP($D24,'Solution Pnode'!$F:$L,6,FALSE) -> 0 | N24: =J24-E24 -> 0 | O24: =K24-F24 -> 0 | P24: =L24-G24 -> 0
A25: 191012024062345498 | B25: 45463.49 | C25: TP24 | D25: AVI2201 AVI0 | E25: 104.218 | F25: 0 | G25: 193.2498 | H25: 0 | I25: 0 | J25: =VLOOKUP($D25,'Solution Pnode'!$F:$L,5,FALSE) -> 104.218 | K25: =VLOOKUP($D25,'Solution Pnode'!$F:$L,4,FALSE) -> 0 | L25: =VLOOKUP($D25,'Solution Pnode'!$F:$L,7,FALSE) -> 193.2498 | M25: =VLOOKUP($D25,'Solution Pnode'!$F:$L,6,FALSE) -> 93.6 | N25: =J25-E25 -> 0 | O25: =K25-F25 -> 0 | P25: =L25-G25 -> 0
A26: 191012024062345498 | B26: 45463.49 | C26: TP24 | D26: BAL0331 | E26: 0 | F26: 20.5214 | G26: 206.4871 | H26: 0 | I26: 0 | J26: =VLOOKUP($D26,'Solution Pnode'!$F:$L,5,FALSE) -> 0 | K26: =VLOOKUP($D26,'Solution Pnode'!$F:$L,4,FALSE) -> 20.5214 | L26: =VLOOKUP($D26,'Solution Pnode'!$F:$L,7,FALSE) -> 206.4871 | M26: =VLOOKUP($D26,'Solution Pnode'!$F:$L,6,FALSE) -> 20.661 | N26: =J26-E26 -> 0 | O26: =K26-F26 -> 0 | P26: =L26-G26 -> 0
A27: 191012024062345498 | B27: 45463.49 | C27: TP24 | D27: BAL1101 | E27: 0 | F27: 0 | G27: 203.9434 | H27: 0 | I27: 0 | J27: =VLOOKUP($D27,'Solution Pnode'!$F:$L,5,FALSE) -> 0 | K27: =VLOOKUP($D27,'Solution Pnode'!$F:$L,4,FALSE) -> 0 | L27: =VLOOKUP($D27,'Solution Pnode'!$F:$L,7,FALSE) -> 203.9434 | M27: =VLOOKUP($D27,'Solution Pnode'!$F:$L,6,FALSE) -> 0 | N27: =J27-E27 -> 0 | O27: =K27-F27 -> 0 | P27: =L27-G27 -> 0
A28: 191012024062345498 | B28: 45463.49 | C28: TP24 | D28: BDE0111 | E28: 0 | F28: 3.079 | G28: 195.6464 | H28: 0 | I28: 0 | J28: =VLOOKUP($D28,'Solution Pnode'!$F:$L,5,FALSE) -> 0 | K28: =VLOOKUP($D28,'Solution Pnode'!$F:$L,4,FALSE) -> 3.079 | L28: =VLOOKUP($D28,'Solution Pnode'!$F:$L,7,FALSE) -> 195.6464 | M28: =VLOOKUP($D28,'Solution Pnode'!$F:$L,6,FALSE) -> 3.1 | N28: =J28-E28 -> 0 | O28: =K28-F28 -> 0 | P28: =L28-G28 -> 0
A29: 191012024062345498 | B29: 45463.49 | C29: TP24 | D29: BDE1101 | E29: 0 | F29: 0 | G29: 195.5131 | H29: 0 | I29: 0 | J29: =VLOOKUP($D29,'Solution Pnode'!$F:$L,5,FALSE) -> 0 | K29: =VLOOKUP($D29,'Solution Pnode'!$F:$L,4,FALSE) -> 0 | L29: =VLOOKUP($D29,'Solution Pnode'!$F:$L,7,FALSE) -> 195.5131 | M29: =VLOOKUP($D29,'Solution Pnode'!$F:$L,6,FALSE) -> 0 | N29: =J29-E29 -> 0 | O29: =K29-F29 -> 0 | P29: =L29-G29 -> 0
A30: 191012024062345498 | B30: 45463.49 | C30: TP24 | D30: BEN2201 | E30: 0 | F30: 0 | G30: 193.1423 | H30: 0 | I30: 0 | J30: =VLOOKUP($D30,'Solution Pnode'!$F:$L,5,FALSE) -> 0 | K30: =VLOOKUP($D30,'Solution Pnode'!$F:$L,4,FALSE) -> 0 | L30: =VLOOKUP($D30,'Solution Pnode'!$F:$L,7,FALSE) -> 193.1423 | M30: =VLOOKUP($D30,'Solution Pnode'!$F:$L,6,FALSE) -> 0 | N30: =J30-E30 -> 0 | O30: =K30-F30 -> 0 | P30: =L30-G30 -> 0
A31: 191012024062345498 | B31: 45463.49 | C31: TP24 | D31: BEN2202 | E31: 0 | F31: 0 | G31: 193.1423 | H31: 0 | I31: 0 | J31: =VLOOKUP($D31,'Solution Pnode'!$F:$L,5,FALSE) -> 0 | K31: =VLOOKUP($D31,'Solution Pnode'!$F:$L,4,FALSE) -> 0 | L31: =VLOOKUP($D31,'Solution Pnode'!$F:$L,7,FALSE) -> 193.1423 | M31: =VLOOKUP($D31,'Solution Pnode'!$F:$L,6,FALSE) -> 0 | N31: =J31-E31 -> 0 | O31: =K31-F31 -> 0 | P31: =L31-G31 -> 0
A32: 191012024062345498 | B32: 45463.49 | C32: TP24 | D32: BEN2202 BEN0 | E32: 227.341 | F32: 0 | G32: 193.1423 | H32: 0 | I32: 0 | J32: =VLOOKUP($D32,'Solution Pnode'!$F:$L,5,FALSE) -> 227.341 | K32: =VLOOKUP($D32,'Solution Pnode'!$F:$L,4,FALSE) -> 0 | L32: =VLOOKUP($D32,'Solution Pnode'!$F:$L,7,FALSE) -> 193.1423 | M32: =VLOOKUP($D32,'Solution Pnode'!$F:$L,6,FALSE) -> 147.98 | N32: =J32-E32 -> 0 | O32: =K32-F32 -> 0 | P32: =L32-G32 -> 0
A33: 191012024062345498 | B33: 45463.49 | C33: TP24 | D33: BEN3502 | E33: 0 | F33: 0 | G33: 193.1423 | H33: 0 | I33: 0 | J33: =VLOOKUP($D33,'Solution Pnode'!$F:$L,5,FALSE) -> 0 | K33: =VLOOKUP($D33,'Solution Pnode'!$F:$L,4,FALSE) -> 0 | L33: =VLOOKUP($D33,'Solution Pnode'!$F:$L,7,FALSE) -> 193.1423 | M33: =VLOOKUP($D33,'Solution Pnode'!$F:$L,6,FALSE) -> 0 | N33: =J33-E33 -> 0 | O33: =K33-F33 -> 0 | P33: =L33-G33 -> 0
A34: 191012024062345498 | B34: 45463.49 | C34: TP24 | D34: BEN3503 | E34: 0 | F34: 0 | G34: 193.1423 | H34: 0 | I34: 0 | J34: =VLOOKUP($D34,'Solution Pnode'!$F:$L,5,FALSE) -> 0 | K34: =VLOOKUP($D34,'Solution Pnode'!$F:$L,4,FALSE) -> 0 | L34: =VLOOKUP($D34,'Solution Pnode'!$F:$L,7,FALSE) -> 193.1423 | M34: =VLOOKUP($D34,'Solution Pnode'!$F:$L,6,FALSE) -> 0 | N34: =J34-E34 -> 0 | O34: =K34-F34 -> 0 | P34: =L34-G34 -> 0
A35: 191012024062345498 | B35: 45463.49 | C35: TP24 | D35: BHL2201 | E35: 0 | F35: 0 | G35: 192.8894 | H35: 0 | I35: 0 | J35: =VLOOKUP($D35,'Solution Pnode'!$F:$L,5,FALSE) -> 0 | K35: =VLOOKUP($D35,'Solution Pnode'!$F:$L,4,FALSE) -> 0 | L35: =VLOOKUP($D35,'Solution Pnode'!$F:$L,7,FALSE) -> 192.8894 | M35: =VLOOKUP($D35,'Solution Pnode'!$F:$L,6,FALSE) -> 0 | N35: =J35-E35 -> 0 | O35: =K35-F35 -> 0 | P35: =L35-G35 -> 0
... A537: 191012024062345498 | B537: 45463.49 | C537: TP24 | D537: WWD1103 WWD0 | E537: 0 | F537: 0 | G537: 195.4184 | H537: 0 | I537: 0 | J537: =VLOOKUP($D537,'Solution Pnode'!$F:$L,5,FALSE) -> 0 | K537: =VLOOKUP($D537,'Solution Pnode'!$F:$L,4,FALSE) -> 0 | L537: =VLOOKUP($D537,'Solution Pnode'!$F:$L,7,FALSE) -> 195.4184 | M537: =VLOOKUP($D537,'Solution Pnode'!$F:$L,6,FALSE) -> 0 | N537: =J537-E537 -> 0 | O537: =K537-F537 -> 0 | P537: =L537-G537 -> 0
W557: =18/10000 -> 0.0018
W558: =W557/0.0002 -> 9

Sheet TraderPeriod_solution
A1: I | B1: SOLUTION | C1: TRADERPERIOD | D1: 1 | E1: INTERVAL | F1: TRADERID | G1: TRADETYPE | H1: PNODENAME | I1: MWCLEARED | J1: RESERVECLEAREDSIXSEC | K1: RESERVECLEAREDSIXTYSEC | L1: UPRAMPRATE | M1: UPRAMPRATEBROKENMW | N1: DNRAMPRATE | O1: DNRAMPRATEBROKENMW | P1: GENRISKSIXSEC | Q1: GENRISKSIXTYSEC | R1: TRADERBLOCKALTKEY | S1: UPRAMPRATEBINDING | T1: DNRAMPRATEBINDING | U1: PRICECLEARED | V1: DIFFBIDSPOSCLEARED | W1: DIFFBIDSNEGCLEARED | X1: IGPOTENTIALMW | Y1: DISPATCHABLE | Z1: DDBIDSLIMIT
A2: D | B2: SOLUTION | C2: TRADERPERIOD | D2: 1 | E2: 45463.49 | F2: 38486 | G2: ENOF | H2: ARA2201 ARA0 | I2: 47 | J2: 0 | K2: 0 | L2: 0 | M2: 0 | N2: 0 | O2: 0 | P2: 0 | Q2: 0 | R2: 5456009624 | S2: 0 | T2: 0 | U2: 0.49 | V2: 0 | W2: 0 | X2: 9999 | Y2: 1 | Z2: 0
A3: D | B3: SOLUTION | C3: TRADERPERIOD | D3: 1 | E3: 45463.49 | F3: 38486 | G3: PLRO | H3: ARA2201 ARA0 | I3: 0 | J3: 0.987 | K3: 3 | L3: 0 | M3: 0 | N3: 0 | O3: 0 | P3: 0 | Q3: 0 | R3: 5455942776 | S3: 0 | T3: 0 | U3: 0.01 | V3: 0 | W3: 0 | X3: 9999 | Y3: 1 | Z3: 0
A4: D | B4: SOLUTION | C4: TRADERPERIOD | D4: 1 | E4: 45463.49 | F4: 38486 | G4: TWRO | H4: ARA2201 ARA0 | I4: 0 | J4: 0 | K4: 0 | L4: 0 | M4: 0 | N4: 0 | O4: 0 | P4: 0 | Q4: 0 | R4: 5455942777 | S4: 0 | T4: 0 | U4: 0 | V4: 0 | W4: 0 | X4: 9999 | Y4: 1 | Z4: 0
A5: D | B5: SOLUTION | C5: TRADERPERIOD | D5: 1 | E5: 45463.49 | F5: 4089922724 | G5: ENOF | H5: ARG1101 BRR0 | I5: 11 | J5: 0 | K5: 0 | L5: 0 | M5: 0 | N5: 0 | O5: 0 | P5: 0 | Q5: 0 | R5: 5455168868 | S5: 0 | T5: 0 | U5: 200 | V5: 0 | W5: 0 | X5: 9999 | Y5: 1 | Z5: 0
A6: D | B6: SOLUTION | C6: TRADERPERIOD | D6: 1 | E6: 45463.49 | F6: 38486 | G6: ENOF | H6: ARI1101 ARI0 | I6: 46 | J6: 0 | K6: 0 | L6: 0 | M6: 0 | N6: 0 | O6: 0 | P6: 0 | Q6: 0 | R6: 5456009626 | S6: 0 | T6: 0 | U6: 0.49 | V6: 0 | W6: 0 | X6: 9999 | Y6: 1 | Z6: 0
A7: D | B7: SOLUTION | C7: TRADERPERIOD | D7: 1 | E7: 45463.49 | F7: 38486 | G7: PLRO | H7: ARI1101 ARI0 | I7: 0 | J7: 0 | K7: 0 | L7: 0 | M7: 0 | N7: 0 | O7: 0 | P7: 0 | Q7: 0 | R7: 5455942780 | S7: 0 | T7: 0 | U7: 0 | V7: 0 | W7: 0 | X7: 9999 | Y7: 1 | Z7: 0
A8: D | B8: SOLUTION | C8: TRADERPERIOD | D8: 1 | E8: 45463.49 | F8: 38486 | G8: TWRO | H8: ARI1101 ARI0 | I8: 0 | J8: 0 | K8: 0 | L8: 0 | M8: 0 | N8: 0 | O8: 0 | P8: 0 | Q8: 0 | R8: 5455942781 | S8: 0 | T8: 0 | U8: 0 | V8: 0 | W8: 0 | X8: 9999 | Y8: 1 | Z8: 0
A9: D | B9: SOLUTION | C9: TRADERPERIOD | D9: 1 | E9: 45463.49 | F9: 38486 | G9: ENOF | H9: ARI1102 ARI0 | I9: 40 | J9: 0 | K9: 0 | L9: 0 | M9: 0 | N9: 0 | O9: 0 | P9: 0 | Q9: 0 | R9: 5456009640 | S9: 0 | T9: 0 | U9: 0.49 | V9: 0 | W9: 0 | X9: 9999 | Y9: 1 | Z9: 0
A10: D | B10: SOLUTION | C10: TRADERPERIOD | D10: 1 | E10: 45463.49 | F10: 38486 | G10: PLRO | H10: ARI1102 ARI0 | I10: 0 | J10: 1 | K10: 3 | L10: 0 | M10: 0 | N10: 0 | O10: 0 | P10: 0 | Q10: 0 | R10: 5455942808 | S10: 0 | T10: 0 | U10: 0.01 | V10: 0 | W10: 0 | X10: 9999 | Y10: 1 | Z10: 0
A11: D | B11: SOLUTION | C11: TRADERPERIOD | D11: 1 | E11: 45463.49 | F11: 38486 | G11: TWRO | H11: ARI1102 ARI0 | I11: 0 | J11: 0 | K11: 0 | L11: 0 | M11: 0 | N11: 0 | O11: 0 | P11: 0 | Q11: 0 | R11: 5455942809 | S11: 0 | T11: 0 | U11: 0 | V11: 0 | W11: 0 | X11: 9999 | Y11: 1 | Z11: 0
A12: D | B12: SOLUTION | C12: TRADERPERIOD | D12: 1 | E12: 45463.49 | F12: 4089922724 | G12: ENOF | H12: ASB0661 HBK0 | I12: 22 | J12: 0 | K12: 0 | L12: 0 | M12: 0 | N12: 0 | O12: 0 | P12: 0 | Q12: 0 | R12: 5455910510 | S12: 0 | T12: 0 | U12: 0.001 | V12: 0 | W12: 0 | X12: 9999 | Y12: 1 | Z12: 0
A13: D | B13: SOLUTION | C13: TRADERPERIOD | D13: 1 | E13: 45463.49 | F13: 38486 | G13: ENOF | H13: ATI2201 ATI0 | I13: 51 | J13: 0 | K13: 0 | L13: 0 | M13: 0 | N13: 0 | O13: 0 | P13: 0 | Q13: 0 | R13: 5456009628 | S13: 0 | T13: 0 | U13: 180 | V13: 0 | W13: 0 | X13: 9999 | Y13: 1 | Z13: 0
... A195: D | B195: SOLUTION | C195: TRADERPERIOD | D195: 1 | E195: 45463.49 | F195: 38481 | G195: ENOF | H195: WWD1103 WWD0 | I195: 0 | J195: 0 | K195: 0 | L195: 0 | M195: 0 | N195: 0 | O195: 0 | P195: 0 | Q195: 0 | R195: 5456127716 | S195: 0 | T195: 0 | U195: 0 | V195: 0 | W195: 0 | X195: 0 | Y195: 1 | Z195: 0
